
*********************
*********************
Running Python file: x-pytorch_noise
*********************

2020-11-20 22:16:15.495022: W tensorflow/stream_executor/platform/default/dso_loader.cc:59] Could not load dynamic library 'libcudart.so.10.1'; dlerror: libcudart.so.10.1: cannot open shared object file: No such file or directory
2020-11-20 22:16:15.495097: I tensorflow/stream_executor/cuda/cudart_stub.cc:29] Ignore above cudart dlerror if you do not have a GPU set up on your machine.
WARNING:urllib3.connectionpool:Retrying (Retry(total=2, connect=None, read=None, redirect=None, status=None)) after connection broken by 'NewConnectionError('<urllib3.connection.HTTPConnection object at 0x7f74f2f08cd0>: Failed to establish a new connection: [Errno 111] Connection refused')': /
WARNING:urllib3.connectionpool:Retrying (Retry(total=1, connect=None, read=None, redirect=None, status=None)) after connection broken by 'NewConnectionError('<urllib3.connection.HTTPConnection object at 0x7f74f2f08e50>: Failed to establish a new connection: [Errno 111] Connection refused')': /
WARNING:urllib3.connectionpool:Retrying (Retry(total=0, connect=None, read=None, redirect=None, status=None)) after connection broken by 'NewConnectionError('<urllib3.connection.HTTPConnection object at 0x7f74f2eafb10>: Failed to establish a new connection: [Errno 111] Connection refused')': /
Traceback (most recent call last):
  File "/workspace/.pip-modules/lib/python3.7/site-packages/urllib3/connection.py", line 170, in _new_conn
    (self._dns_host, self.port), self.timeout, **extra_kw
  File "/workspace/.pip-modules/lib/python3.7/site-packages/urllib3/util/connection.py", line 96, in create_connection
    raise err
  File "/workspace/.pip-modules/lib/python3.7/site-packages/urllib3/util/connection.py", line 86, in create_connection
    sock.connect(sa)
ConnectionRefusedError: [Errno 111] Connection refused

During handling of the above exception, another exception occurred:

Traceback (most recent call last):
  File "/workspace/.pip-modules/lib/python3.7/site-packages/urllib3/connectionpool.py", line 706, in urlopen
    chunked=chunked,
  File "/workspace/.pip-modules/lib/python3.7/site-packages/urllib3/connectionpool.py", line 394, in _make_request
    conn.request(method, url, **httplib_request_kw)
  File "/workspace/.pip-modules/lib/python3.7/site-packages/urllib3/connection.py", line 234, in request
    super(HTTPConnection, self).request(method, url, body=body, headers=headers)
  File "/home/gitpod/.pyenv/versions/3.7.4/lib/python3.7/http/client.py", line 1244, in request
    self._send_request(method, url, body, headers, encode_chunked)
  File "/home/gitpod/.pyenv/versions/3.7.4/lib/python3.7/http/client.py", line 1290, in _send_request
    self.endheaders(body, encode_chunked=encode_chunked)
  File "/home/gitpod/.pyenv/versions/3.7.4/lib/python3.7/http/client.py", line 1239, in endheaders
    self._send_output(message_body, encode_chunked=encode_chunked)
  File "/home/gitpod/.pyenv/versions/3.7.4/lib/python3.7/http/client.py", line 1026, in _send_output
    self.send(msg)
  File "/home/gitpod/.pyenv/versions/3.7.4/lib/python3.7/http/client.py", line 966, in send
    self.connect()
  File "/workspace/.pip-modules/lib/python3.7/site-packages/urllib3/connection.py", line 200, in connect
    conn = self._new_conn()
  File "/workspace/.pip-modules/lib/python3.7/site-packages/urllib3/connection.py", line 182, in _new_conn
    self, "Failed to establish a new connection: %s" % e
urllib3.exceptions.NewConnectionError: <urllib3.connection.HTTPConnection object at 0x7f74f2eca210>: Failed to establish a new connection: [Errno 111] Connection refused

During handling of the above exception, another exception occurred:

Traceback (most recent call last):
  File "/workspace/.pip-modules/lib/python3.7/site-packages/requests/adapters.py", line 449, in send
    timeout=timeout
  File "/workspace/.pip-modules/lib/python3.7/site-packages/urllib3/connectionpool.py", line 796, in urlopen
    **response_kw
  File "/workspace/.pip-modules/lib/python3.7/site-packages/urllib3/connectionpool.py", line 796, in urlopen
    **response_kw
  File "/workspace/.pip-modules/lib/python3.7/site-packages/urllib3/connectionpool.py", line 796, in urlopen
    **response_kw
  File "/workspace/.pip-modules/lib/python3.7/site-packages/urllib3/connectionpool.py", line 756, in urlopen
    method, url, error=e, _pool=self, _stacktrace=sys.exc_info()[2]
  File "/workspace/.pip-modules/lib/python3.7/site-packages/urllib3/util/retry.py", line 573, in increment
    raise MaxRetryError(_pool, url, error or ResponseError(cause))
urllib3.exceptions.MaxRetryError: HTTPConnectionPool(host='127.0.0.1', port=5000): Max retries exceeded with url: / (Caused by NewConnectionError('<urllib3.connection.HTTPConnection object at 0x7f74f2eca210>: Failed to establish a new connection: [Errno 111] Connection refused'))

During handling of the above exception, another exception occurred:

Traceback (most recent call last):
  File "/workspace/.pip-modules/lib/python3.7/site-packages/pyquil/api/_qvm.py", line 492, in connect
    version_dict = self.get_version_info()
  File "/workspace/.pip-modules/lib/python3.7/site-packages/pyquil/api/_error_reporting.py", line 251, in wrapper
    val = func(*args, **kwargs)
  File "/workspace/.pip-modules/lib/python3.7/site-packages/pyquil/api/_qvm.py", line 504, in get_version_info
    return cast(str, self.connection._qvm_get_version_info())
  File "/workspace/.pip-modules/lib/python3.7/site-packages/pyquil/api/_error_reporting.py", line 251, in wrapper
    val = func(*args, **kwargs)
  File "/workspace/.pip-modules/lib/python3.7/site-packages/pyquil/api/_base_connection.py", line 625, in _qvm_get_version_info
    response = post_json(self.session, self.sync_endpoint, {"type": "version"})
  File "/workspace/.pip-modules/lib/python3.7/site-packages/pyquil/api/_base_connection.py", line 63, in post_json
    res = session.post(url, json=json)
  File "/workspace/.pip-modules/lib/python3.7/site-packages/requests/sessions.py", line 590, in post
    return self.request('POST', url, data=data, json=json, **kwargs)
  File "/workspace/.pip-modules/lib/python3.7/site-packages/pyquil/api/_base_connection.py", line 469, in request
    response = super().request(*args, **kwargs)
  File "/workspace/.pip-modules/lib/python3.7/site-packages/requests/sessions.py", line 542, in request
    resp = self.send(prep, **send_kwargs)
  File "/workspace/.pip-modules/lib/python3.7/site-packages/requests/sessions.py", line 655, in send
    r = adapter.send(request, **kwargs)
  File "/workspace/.pip-modules/lib/python3.7/site-packages/requests/adapters.py", line 516, in send
    raise ConnectionError(e, request=request)
requests.exceptions.ConnectionError: HTTPConnectionPool(host='127.0.0.1', port=5000): Max retries exceeded with url: / (Caused by NewConnectionError('<urllib3.connection.HTTPConnection object at 0x7f74f2eca210>: Failed to establish a new connection: [Errno 111] Connection refused'))

During handling of the above exception, another exception occurred:

Traceback (most recent call last):
  File "x-pytorch_noise.py", line 60, in <module>
    dev = qml.device("forest.qvm", device="2q", noisy=True)
  File "/workspace/.pip-modules/lib/python3.7/site-packages/pennylane/__init__.py", line 198, in device
    return plugin_device_class(*args, **options)
  File "/workspace/.pip-modules/lib/python3.7/site-packages/pennylane_forest/qvm.py", line 120, in __init__
    self.qc = get_qc(device, as_qvm=True, noisy=noisy, connection=self.connection)
  File "/workspace/.pip-modules/lib/python3.7/site-packages/pyquil/api/_error_reporting.py", line 251, in wrapper
    val = func(*args, **kwargs)
  File "/workspace/.pip-modules/lib/python3.7/site-packages/pyquil/api/_quantum_computer.py", line 916, in get_qc
    compiler_timeout=compiler_timeout,
  File "/workspace/.pip-modules/lib/python3.7/site-packages/pyquil/api/_quantum_computer.py", line 779, in _get_unrestricted_qvm
    compiler_timeout=compiler_timeout,
  File "/workspace/.pip-modules/lib/python3.7/site-packages/pyquil/api/_quantum_computer.py", line 716, in _get_qvm_with_topology
    compiler_timeout=compiler_timeout,
  File "/workspace/.pip-modules/lib/python3.7/site-packages/pyquil/api/_quantum_computer.py", line 667, in _get_qvm_qc
    requires_executable=requires_executable,
  File "/workspace/.pip-modules/lib/python3.7/site-packages/pyquil/api/_quantum_computer.py", line 624, in _get_qvm_or_pyqvm
    connection=connection, noise_model=noise_model, requires_executable=requires_executable
  File "/workspace/.pip-modules/lib/python3.7/site-packages/pyquil/api/_error_reporting.py", line 251, in wrapper
    val = func(*args, **kwargs)
  File "/workspace/.pip-modules/lib/python3.7/site-packages/pyquil/api/_qvm.py", line 488, in __init__
    self.connect()
  File "/workspace/.pip-modules/lib/python3.7/site-packages/pyquil/api/_qvm.py", line 495, in connect
    raise QVMNotRunning(f"No QVM server running at {self.connection.sync_endpoint}")
pyquil.api._qvm.QVMNotRunning: No QVM server running at http://127.0.0.1:5000

*********************
*********************
Running Python file: x-qonn
*********************

2020-11-20 22:16:44.741822: W tensorflow/stream_executor/platform/default/dso_loader.cc:59] Could not load dynamic library 'libcudart.so.10.1'; dlerror: libcudart.so.10.1: cannot open shared object file: No such file or directory
2020-11-20 22:16:44.741900: I tensorflow/stream_executor/cuda/cudart_stub.cc:29] Ignore above cudart dlerror if you do not have a GPU set up on your machine.
Traceback (most recent call last):
  File "x-qonn.py", line 90, in <module>
    dev = qml.device("strawberryfields.fock", wires=4, cutoff_dim=4)
  File "/workspace/.pip-modules/lib/python3.7/site-packages/pennylane/__init__.py", line 187, in device
    plugin_device_class = plugin_devices[name].load()
  File "/workspace/.pip-modules/lib/python3.7/site-packages/pkg_resources/__init__.py", line 2446, in load
    self.require(*args, **kwargs)
  File "/workspace/.pip-modules/lib/python3.7/site-packages/pkg_resources/__init__.py", line 2469, in require
    items = working_set.resolve(reqs, env, installer, extras=self.extras)
  File "/workspace/.pip-modules/lib/python3.7/site-packages/pkg_resources/__init__.py", line 775, in resolve
    raise VersionConflict(dist, req).with_context(dependent_req)
pkg_resources.ContextualVersionConflict: (sympy 1.5 (/workspace/.pip-modules/lib/python3.7/site-packages), Requirement.parse('sympy>=1.5.1'), {'thewalrus'})

*********************
*********************
Running Python file: x-tutorial_ensemble_multi_qpu
*********************

2020-11-20 22:26:16.100128: W tensorflow/stream_executor/platform/default/dso_loader.cc:59] Could not load dynamic library 'libcudart.so.10.1'; dlerror: libcudart.so.10.1: cannot open shared object file: No such file or directory
2020-11-20 22:26:16.100240: I tensorflow/stream_executor/cuda/cudart_stub.cc:29] Ignore above cudart dlerror if you do not have a GPU set up on your machine.
WARNING:urllib3.connectionpool:Retrying (Retry(total=2, connect=None, read=None, redirect=None, status=None)) after connection broken by 'NewConnectionError('<urllib3.connection.HTTPConnection object at 0x7fd5dad6bcd0>: Failed to establish a new connection: [Errno 111] Connection refused')': /
WARNING:urllib3.connectionpool:Retrying (Retry(total=1, connect=None, read=None, redirect=None, status=None)) after connection broken by 'NewConnectionError('<urllib3.connection.HTTPConnection object at 0x7fd5dadde590>: Failed to establish a new connection: [Errno 111] Connection refused')': /
WARNING:urllib3.connectionpool:Retrying (Retry(total=0, connect=None, read=None, redirect=None, status=None)) after connection broken by 'NewConnectionError('<urllib3.connection.HTTPConnection object at 0x7fd5dad86350>: Failed to establish a new connection: [Errno 111] Connection refused')': /
Traceback (most recent call last):
  File "/workspace/.pip-modules/lib/python3.7/site-packages/urllib3/connection.py", line 170, in _new_conn
    (self._dns_host, self.port), self.timeout, **extra_kw
  File "/workspace/.pip-modules/lib/python3.7/site-packages/urllib3/util/connection.py", line 96, in create_connection
    raise err
  File "/workspace/.pip-modules/lib/python3.7/site-packages/urllib3/util/connection.py", line 86, in create_connection
    sock.connect(sa)
ConnectionRefusedError: [Errno 111] Connection refused

During handling of the above exception, another exception occurred:

Traceback (most recent call last):
  File "/workspace/.pip-modules/lib/python3.7/site-packages/urllib3/connectionpool.py", line 706, in urlopen
    chunked=chunked,
  File "/workspace/.pip-modules/lib/python3.7/site-packages/urllib3/connectionpool.py", line 394, in _make_request
    conn.request(method, url, **httplib_request_kw)
  File "/workspace/.pip-modules/lib/python3.7/site-packages/urllib3/connection.py", line 234, in request
    super(HTTPConnection, self).request(method, url, body=body, headers=headers)
  File "/home/gitpod/.pyenv/versions/3.7.4/lib/python3.7/http/client.py", line 1244, in request
    self._send_request(method, url, body, headers, encode_chunked)
  File "/home/gitpod/.pyenv/versions/3.7.4/lib/python3.7/http/client.py", line 1290, in _send_request
    self.endheaders(body, encode_chunked=encode_chunked)
  File "/home/gitpod/.pyenv/versions/3.7.4/lib/python3.7/http/client.py", line 1239, in endheaders
    self._send_output(message_body, encode_chunked=encode_chunked)
  File "/home/gitpod/.pyenv/versions/3.7.4/lib/python3.7/http/client.py", line 1026, in _send_output
    self.send(msg)
  File "/home/gitpod/.pyenv/versions/3.7.4/lib/python3.7/http/client.py", line 966, in send
    self.connect()
  File "/workspace/.pip-modules/lib/python3.7/site-packages/urllib3/connection.py", line 200, in connect
    conn = self._new_conn()
  File "/workspace/.pip-modules/lib/python3.7/site-packages/urllib3/connection.py", line 182, in _new_conn
    self, "Failed to establish a new connection: %s" % e
urllib3.exceptions.NewConnectionError: <urllib3.connection.HTTPConnection object at 0x7fd5dad86990>: Failed to establish a new connection: [Errno 111] Connection refused

During handling of the above exception, another exception occurred:

Traceback (most recent call last):
  File "/workspace/.pip-modules/lib/python3.7/site-packages/requests/adapters.py", line 449, in send
    timeout=timeout
  File "/workspace/.pip-modules/lib/python3.7/site-packages/urllib3/connectionpool.py", line 796, in urlopen
    **response_kw
  File "/workspace/.pip-modules/lib/python3.7/site-packages/urllib3/connectionpool.py", line 796, in urlopen
    **response_kw
  File "/workspace/.pip-modules/lib/python3.7/site-packages/urllib3/connectionpool.py", line 796, in urlopen
    **response_kw
  File "/workspace/.pip-modules/lib/python3.7/site-packages/urllib3/connectionpool.py", line 756, in urlopen
    method, url, error=e, _pool=self, _stacktrace=sys.exc_info()[2]
  File "/workspace/.pip-modules/lib/python3.7/site-packages/urllib3/util/retry.py", line 573, in increment
    raise MaxRetryError(_pool, url, error or ResponseError(cause))
urllib3.exceptions.MaxRetryError: HTTPConnectionPool(host='127.0.0.1', port=5000): Max retries exceeded with url: / (Caused by NewConnectionError('<urllib3.connection.HTTPConnection object at 0x7fd5dad86990>: Failed to establish a new connection: [Errno 111] Connection refused'))

During handling of the above exception, another exception occurred:

Traceback (most recent call last):
  File "/workspace/.pip-modules/lib/python3.7/site-packages/pyquil/api/_qvm.py", line 492, in connect
    version_dict = self.get_version_info()
  File "/workspace/.pip-modules/lib/python3.7/site-packages/pyquil/api/_error_reporting.py", line 251, in wrapper
    val = func(*args, **kwargs)
  File "/workspace/.pip-modules/lib/python3.7/site-packages/pyquil/api/_qvm.py", line 504, in get_version_info
    return cast(str, self.connection._qvm_get_version_info())
  File "/workspace/.pip-modules/lib/python3.7/site-packages/pyquil/api/_error_reporting.py", line 251, in wrapper
    val = func(*args, **kwargs)
  File "/workspace/.pip-modules/lib/python3.7/site-packages/pyquil/api/_base_connection.py", line 625, in _qvm_get_version_info
    response = post_json(self.session, self.sync_endpoint, {"type": "version"})
  File "/workspace/.pip-modules/lib/python3.7/site-packages/pyquil/api/_base_connection.py", line 63, in post_json
    res = session.post(url, json=json)
  File "/workspace/.pip-modules/lib/python3.7/site-packages/requests/sessions.py", line 590, in post
    return self.request('POST', url, data=data, json=json, **kwargs)
  File "/workspace/.pip-modules/lib/python3.7/site-packages/pyquil/api/_base_connection.py", line 469, in request
    response = super().request(*args, **kwargs)
  File "/workspace/.pip-modules/lib/python3.7/site-packages/requests/sessions.py", line 542, in request
    resp = self.send(prep, **send_kwargs)
  File "/workspace/.pip-modules/lib/python3.7/site-packages/requests/sessions.py", line 655, in send
    r = adapter.send(request, **kwargs)
  File "/workspace/.pip-modules/lib/python3.7/site-packages/requests/adapters.py", line 516, in send
    raise ConnectionError(e, request=request)
requests.exceptions.ConnectionError: HTTPConnectionPool(host='127.0.0.1', port=5000): Max retries exceeded with url: / (Caused by NewConnectionError('<urllib3.connection.HTTPConnection object at 0x7fd5dad86990>: Failed to establish a new connection: [Errno 111] Connection refused'))

During handling of the above exception, another exception occurred:

Traceback (most recent call last):
  File "x-tutorial_ensemble_multi_qpu.py", line 166, in <module>
    dev0 = qml.device("forest.qvm", device="4q-qvm")
  File "/workspace/.pip-modules/lib/python3.7/site-packages/pennylane/__init__.py", line 198, in device
    return plugin_device_class(*args, **options)
  File "/workspace/.pip-modules/lib/python3.7/site-packages/pennylane_forest/qvm.py", line 120, in __init__
    self.qc = get_qc(device, as_qvm=True, noisy=noisy, connection=self.connection)
  File "/workspace/.pip-modules/lib/python3.7/site-packages/pyquil/api/_error_reporting.py", line 251, in wrapper
    val = func(*args, **kwargs)
  File "/workspace/.pip-modules/lib/python3.7/site-packages/pyquil/api/_quantum_computer.py", line 916, in get_qc
    compiler_timeout=compiler_timeout,
  File "/workspace/.pip-modules/lib/python3.7/site-packages/pyquil/api/_quantum_computer.py", line 779, in _get_unrestricted_qvm
    compiler_timeout=compiler_timeout,
  File "/workspace/.pip-modules/lib/python3.7/site-packages/pyquil/api/_quantum_computer.py", line 716, in _get_qvm_with_topology
    compiler_timeout=compiler_timeout,
  File "/workspace/.pip-modules/lib/python3.7/site-packages/pyquil/api/_quantum_computer.py", line 667, in _get_qvm_qc
    requires_executable=requires_executable,
  File "/workspace/.pip-modules/lib/python3.7/site-packages/pyquil/api/_quantum_computer.py", line 624, in _get_qvm_or_pyqvm
    connection=connection, noise_model=noise_model, requires_executable=requires_executable
  File "/workspace/.pip-modules/lib/python3.7/site-packages/pyquil/api/_error_reporting.py", line 251, in wrapper
    val = func(*args, **kwargs)
  File "/workspace/.pip-modules/lib/python3.7/site-packages/pyquil/api/_qvm.py", line 488, in __init__
    self.connect()
  File "/workspace/.pip-modules/lib/python3.7/site-packages/pyquil/api/_qvm.py", line 495, in connect
    raise QVMNotRunning(f"No QVM server running at {self.connection.sync_endpoint}")
pyquil.api._qvm.QVMNotRunning: No QVM server running at http://127.0.0.1:5000

*********************
*********************
Running Python file: x-tutorial_noisy_circuit_optimization
*********************

2020-11-20 22:26:28.800093: W tensorflow/stream_executor/platform/default/dso_loader.cc:59] Could not load dynamic library 'libcudart.so.10.1'; dlerror: libcudart.so.10.1: cannot open shared object file: No such file or directory
2020-11-20 22:26:28.800170: I tensorflow/stream_executor/cuda/cudart_stub.cc:29] Ignore above cudart dlerror if you do not have a GPU set up on your machine.
Traceback (most recent call last):
  File "x-tutorial_noisy_circuit_optimization.py", line 86, in <module>
    dev = qml.device("cirq.mixedsimulator", wires=2)
  File "/workspace/.pip-modules/lib/python3.7/site-packages/pennylane/__init__.py", line 187, in device
    plugin_device_class = plugin_devices[name].load()
  File "/workspace/.pip-modules/lib/python3.7/site-packages/pkg_resources/__init__.py", line 2446, in load
    self.require(*args, **kwargs)
  File "/workspace/.pip-modules/lib/python3.7/site-packages/pkg_resources/__init__.py", line 2469, in require
    items = working_set.resolve(reqs, env, installer, extras=self.extras)
  File "/workspace/.pip-modules/lib/python3.7/site-packages/pkg_resources/__init__.py", line 775, in resolve
    raise VersionConflict(dist, req).with_context(dependent_req)
pkg_resources.ContextualVersionConflict: (six 1.12.0 (/home/gitpod/.pyenv/versions/3.7.4/lib/python3.7/site-packages), Requirement.parse('six>=1.13.0'), {'google-api-core'})

*********************
*********************
Running Python file: x-tutorial_plugins_hybrid
*********************

2020-11-20 22:26:42.843996: W tensorflow/stream_executor/platform/default/dso_loader.cc:59] Could not load dynamic library 'libcudart.so.10.1'; dlerror: libcudart.so.10.1: cannot open shared object file: No such file or directory
2020-11-20 22:26:42.844076: I tensorflow/stream_executor/cuda/cudart_stub.cc:29] Ignore above cudart dlerror if you do not have a GPU set up on your machine.
Traceback (most recent call last):
  File "x-tutorial_plugins_hybrid.py", line 140, in <module>
    dev_fock = qml.device("strawberryfields.fock", wires=2, cutoff_dim=2)
  File "/workspace/.pip-modules/lib/python3.7/site-packages/pennylane/__init__.py", line 187, in device
    plugin_device_class = plugin_devices[name].load()
  File "/workspace/.pip-modules/lib/python3.7/site-packages/pkg_resources/__init__.py", line 2446, in load
    self.require(*args, **kwargs)
  File "/workspace/.pip-modules/lib/python3.7/site-packages/pkg_resources/__init__.py", line 2469, in require
    items = working_set.resolve(reqs, env, installer, extras=self.extras)
  File "/workspace/.pip-modules/lib/python3.7/site-packages/pkg_resources/__init__.py", line 775, in resolve
    raise VersionConflict(dist, req).with_context(dependent_req)
pkg_resources.ContextualVersionConflict: (antlr4-python3-runtime 4.7.2 (/workspace/.pip-modules/lib/python3.7/site-packages), Requirement.parse('antlr4-python3-runtime==4.8'), {'quantum-blackbird'})

*********************
*********************
Running Python file: x-tutorial_QGAN
*********************

2020-11-20 22:26:52.866263: W tensorflow/stream_executor/platform/default/dso_loader.cc:59] Could not load dynamic library 'libcudart.so.10.1'; dlerror: libcudart.so.10.1: cannot open shared object file: No such file or directory
2020-11-20 22:26:52.866342: I tensorflow/stream_executor/cuda/cudart_stub.cc:29] Ignore above cudart dlerror if you do not have a GPU set up on your machine.
Traceback (most recent call last):
  File "x-tutorial_QGAN.py", line 52, in <module>
    dev = qml.device('cirq.simulator', wires=3)
  File "/workspace/.pip-modules/lib/python3.7/site-packages/pennylane/__init__.py", line 187, in device
    plugin_device_class = plugin_devices[name].load()
  File "/workspace/.pip-modules/lib/python3.7/site-packages/pkg_resources/__init__.py", line 2446, in load
    self.require(*args, **kwargs)
  File "/workspace/.pip-modules/lib/python3.7/site-packages/pkg_resources/__init__.py", line 2469, in require
    items = working_set.resolve(reqs, env, installer, extras=self.extras)
  File "/workspace/.pip-modules/lib/python3.7/site-packages/pkg_resources/__init__.py", line 775, in resolve
    raise VersionConflict(dist, req).with_context(dependent_req)
pkg_resources.ContextualVersionConflict: (six 1.12.0 (/home/gitpod/.pyenv/versions/3.7.4/lib/python3.7/site-packages), Requirement.parse('six>=1.13.0'), {'google-api-core'})

*********************
*********************
Running Python file: x-tutorial_quantum_metrology
*********************

2020-11-20 22:27:08.223003: W tensorflow/stream_executor/platform/default/dso_loader.cc:59] Could not load dynamic library 'libcudart.so.10.1'; dlerror: libcudart.so.10.1: cannot open shared object file: No such file or directory
2020-11-20 22:27:08.223091: I tensorflow/stream_executor/cuda/cudart_stub.cc:29] Ignore above cudart dlerror if you do not have a GPU set up on your machine.
Traceback (most recent call last):
  File "x-tutorial_quantum_metrology.py", line 135, in <module>
    dev = qml.device("cirq.mixedsimulator", wires=3)
  File "/workspace/.pip-modules/lib/python3.7/site-packages/pennylane/__init__.py", line 187, in device
    plugin_device_class = plugin_devices[name].load()
  File "/workspace/.pip-modules/lib/python3.7/site-packages/pkg_resources/__init__.py", line 2446, in load
    self.require(*args, **kwargs)
  File "/workspace/.pip-modules/lib/python3.7/site-packages/pkg_resources/__init__.py", line 2469, in require
    items = working_set.resolve(reqs, env, installer, extras=self.extras)
  File "/workspace/.pip-modules/lib/python3.7/site-packages/pkg_resources/__init__.py", line 775, in resolve
    raise VersionConflict(dist, req).with_context(dependent_req)
pkg_resources.ContextualVersionConflict: (six 1.12.0 (/home/gitpod/.pyenv/versions/3.7.4/lib/python3.7/site-packages), Requirement.parse('six>=1.13.0'), {'google-api-core'})

*********************
*********************
Running Python file: x-tutorial_quantum_transfer_learning
*********************

2020-11-20 22:27:20.755230: W tensorflow/stream_executor/platform/default/dso_loader.cc:59] Could not load dynamic library 'libcudart.so.10.1'; dlerror: libcudart.so.10.1: cannot open shared object file: No such file or directory
2020-11-20 22:27:20.755304: I tensorflow/stream_executor/cuda/cudart_stub.cc:29] Ignore above cudart dlerror if you do not have a GPU set up on your machine.
Traceback (most recent call last):
  File "x-tutorial_quantum_transfer_learning.py", line 215, in <module>
    for x in ["train", "val"]
  File "x-tutorial_quantum_transfer_learning.py", line 215, in <dictcomp>
    for x in ["train", "val"]
  File "/workspace/.pip-modules/lib/python3.7/site-packages/torchvision/datasets/folder.py", line 229, in __init__
    is_valid_file=is_valid_file)
  File "/workspace/.pip-modules/lib/python3.7/site-packages/torchvision/datasets/folder.py", line 108, in __init__
    classes, class_to_idx = self._find_classes(self.root)
  File "/workspace/.pip-modules/lib/python3.7/site-packages/torchvision/datasets/folder.py", line 137, in _find_classes
    classes = [d.name for d in os.scandir(dir) if d.is_dir()]
FileNotFoundError: [Errno 2] No such file or directory: '../_data/hymenoptera_data/train'

*********************
*********************
Running Python file: z-quantum_neural_net
*********************

2020-11-20 22:27:28.319114: W tensorflow/stream_executor/platform/default/dso_loader.cc:59] Could not load dynamic library 'libcudart.so.10.1'; dlerror: libcudart.so.10.1: cannot open shared object file: No such file or directory
2020-11-20 22:27:28.319202: I tensorflow/stream_executor/cuda/cudart_stub.cc:29] Ignore above cudart dlerror if you do not have a GPU set up on your machine.
Traceback (most recent call last):
  File "z-quantum_neural_net.py", line 44, in <module>
    dev = qml.device("strawberryfields.fock", wires=1, cutoff_dim=10)
  File "/workspace/.pip-modules/lib/python3.7/site-packages/pennylane/__init__.py", line 187, in device
    plugin_device_class = plugin_devices[name].load()
  File "/workspace/.pip-modules/lib/python3.7/site-packages/pkg_resources/__init__.py", line 2446, in load
    self.require(*args, **kwargs)
  File "/workspace/.pip-modules/lib/python3.7/site-packages/pkg_resources/__init__.py", line 2469, in require
    items = working_set.resolve(reqs, env, installer, extras=self.extras)
  File "/workspace/.pip-modules/lib/python3.7/site-packages/pkg_resources/__init__.py", line 775, in resolve
    raise VersionConflict(dist, req).with_context(dependent_req)
pkg_resources.ContextualVersionConflict: (sympy 1.5 (/workspace/.pip-modules/lib/python3.7/site-packages), Requirement.parse('sympy>=1.5.1'), {'thewalrus'})

*********************
*********************
Running Python file: z-tutorial_pasqal
*********************

Open Ports --> Open Preview or Browser --> push enter to continueOpen Ports --> Open Preview or Browser --> push enter to continue2020-11-20 22:28:27.807815: W tensorflow/stream_executor/platform/default/dso_loader.cc:59] Could not load dynamic library 'libcudart.so.10.1'; dlerror: libcudart.so.10.1: cannot open shared object file: No such file or directory
2020-11-20 22:28:27.807892: I tensorflow/stream_executor/cuda/cudart_stub.cc:29] Ignore above cudart dlerror if you do not have a GPU set up on your machine.
Traceback (most recent call last):
  File "z-tutorial_pasqal.py", line 147, in <module>
    qubits=qubits, wires=num_wires)
  File "/workspace/.pip-modules/lib/python3.7/site-packages/pennylane/__init__.py", line 187, in device
    plugin_device_class = plugin_devices[name].load()
  File "/workspace/.pip-modules/lib/python3.7/site-packages/pkg_resources/__init__.py", line 2446, in load
    self.require(*args, **kwargs)
  File "/workspace/.pip-modules/lib/python3.7/site-packages/pkg_resources/__init__.py", line 2469, in require
    items = working_set.resolve(reqs, env, installer, extras=self.extras)
  File "/workspace/.pip-modules/lib/python3.7/site-packages/pkg_resources/__init__.py", line 775, in resolve
    raise VersionConflict(dist, req).with_context(dependent_req)
pkg_resources.ContextualVersionConflict: (six 1.12.0 (/home/gitpod/.pyenv/versions/3.7.4/lib/python3.7/site-packages), Requirement.parse('six>=1.13.0'), {'google-api-core'})

*********************
*********************
Running Python file: z-tutorial_vqe_parallel
*********************

2020-11-20 22:28:47.687896: W tensorflow/stream_executor/platform/default/dso_loader.cc:59] Could not load dynamic library 'libcudart.so.10.1'; dlerror: libcudart.so.10.1: cannot open shared object file: No such file or directory
2020-11-20 22:28:47.687966: I tensorflow/stream_executor/cuda/cudart_stub.cc:29] Ignore above cudart dlerror if you do not have a GPU set up on your machine.
WARNING:urllib3.connectionpool:Retrying (Retry(total=2, connect=None, read=None, redirect=None, status=None)) after connection broken by 'NewConnectionError('<urllib3.connection.HTTPConnection object at 0x7f0271669e90>: Failed to establish a new connection: [Errno 111] Connection refused')': /
WARNING:urllib3.connectionpool:Retrying (Retry(total=1, connect=None, read=None, redirect=None, status=None)) after connection broken by 'NewConnectionError('<urllib3.connection.HTTPConnection object at 0x7f0271678b10>: Failed to establish a new connection: [Errno 111] Connection refused')': /
WARNING:urllib3.connectionpool:Retrying (Retry(total=0, connect=None, read=None, redirect=None, status=None)) after connection broken by 'NewConnectionError('<urllib3.connection.HTTPConnection object at 0x7f0271619090>: Failed to establish a new connection: [Errno 111] Connection refused')': /
Traceback (most recent call last):
  File "/workspace/.pip-modules/lib/python3.7/site-packages/urllib3/connection.py", line 170, in _new_conn
    (self._dns_host, self.port), self.timeout, **extra_kw
  File "/workspace/.pip-modules/lib/python3.7/site-packages/urllib3/util/connection.py", line 96, in create_connection
    raise err
  File "/workspace/.pip-modules/lib/python3.7/site-packages/urllib3/util/connection.py", line 86, in create_connection
    sock.connect(sa)
ConnectionRefusedError: [Errno 111] Connection refused

During handling of the above exception, another exception occurred:

Traceback (most recent call last):
  File "/workspace/.pip-modules/lib/python3.7/site-packages/urllib3/connectionpool.py", line 706, in urlopen
    chunked=chunked,
  File "/workspace/.pip-modules/lib/python3.7/site-packages/urllib3/connectionpool.py", line 394, in _make_request
    conn.request(method, url, **httplib_request_kw)
  File "/workspace/.pip-modules/lib/python3.7/site-packages/urllib3/connection.py", line 234, in request
    super(HTTPConnection, self).request(method, url, body=body, headers=headers)
  File "/home/gitpod/.pyenv/versions/3.7.4/lib/python3.7/http/client.py", line 1244, in request
    self._send_request(method, url, body, headers, encode_chunked)
  File "/home/gitpod/.pyenv/versions/3.7.4/lib/python3.7/http/client.py", line 1290, in _send_request
    self.endheaders(body, encode_chunked=encode_chunked)
  File "/home/gitpod/.pyenv/versions/3.7.4/lib/python3.7/http/client.py", line 1239, in endheaders
    self._send_output(message_body, encode_chunked=encode_chunked)
  File "/home/gitpod/.pyenv/versions/3.7.4/lib/python3.7/http/client.py", line 1026, in _send_output
    self.send(msg)
  File "/home/gitpod/.pyenv/versions/3.7.4/lib/python3.7/http/client.py", line 966, in send
    self.connect()
  File "/workspace/.pip-modules/lib/python3.7/site-packages/urllib3/connection.py", line 200, in connect
    conn = self._new_conn()
  File "/workspace/.pip-modules/lib/python3.7/site-packages/urllib3/connection.py", line 182, in _new_conn
    self, "Failed to establish a new connection: %s" % e
urllib3.exceptions.NewConnectionError: <urllib3.connection.HTTPConnection object at 0x7f0271619750>: Failed to establish a new connection: [Errno 111] Connection refused

During handling of the above exception, another exception occurred:

Traceback (most recent call last):
  File "/workspace/.pip-modules/lib/python3.7/site-packages/requests/adapters.py", line 449, in send
    timeout=timeout
  File "/workspace/.pip-modules/lib/python3.7/site-packages/urllib3/connectionpool.py", line 796, in urlopen
    **response_kw
  File "/workspace/.pip-modules/lib/python3.7/site-packages/urllib3/connectionpool.py", line 796, in urlopen
    **response_kw
  File "/workspace/.pip-modules/lib/python3.7/site-packages/urllib3/connectionpool.py", line 796, in urlopen
    **response_kw
  File "/workspace/.pip-modules/lib/python3.7/site-packages/urllib3/connectionpool.py", line 756, in urlopen
    method, url, error=e, _pool=self, _stacktrace=sys.exc_info()[2]
  File "/workspace/.pip-modules/lib/python3.7/site-packages/urllib3/util/retry.py", line 573, in increment
    raise MaxRetryError(_pool, url, error or ResponseError(cause))
urllib3.exceptions.MaxRetryError: HTTPConnectionPool(host='127.0.0.1', port=5000): Max retries exceeded with url: / (Caused by NewConnectionError('<urllib3.connection.HTTPConnection object at 0x7f0271619750>: Failed to establish a new connection: [Errno 111] Connection refused'))

During handling of the above exception, another exception occurred:

Traceback (most recent call last):
  File "/workspace/.pip-modules/lib/python3.7/site-packages/pyquil/api/_qvm.py", line 492, in connect
    version_dict = self.get_version_info()
  File "/workspace/.pip-modules/lib/python3.7/site-packages/pyquil/api/_error_reporting.py", line 251, in wrapper
    val = func(*args, **kwargs)
  File "/workspace/.pip-modules/lib/python3.7/site-packages/pyquil/api/_qvm.py", line 504, in get_version_info
    return cast(str, self.connection._qvm_get_version_info())
  File "/workspace/.pip-modules/lib/python3.7/site-packages/pyquil/api/_error_reporting.py", line 251, in wrapper
    val = func(*args, **kwargs)
  File "/workspace/.pip-modules/lib/python3.7/site-packages/pyquil/api/_base_connection.py", line 625, in _qvm_get_version_info
    response = post_json(self.session, self.sync_endpoint, {"type": "version"})
  File "/workspace/.pip-modules/lib/python3.7/site-packages/pyquil/api/_base_connection.py", line 63, in post_json
    res = session.post(url, json=json)
  File "/workspace/.pip-modules/lib/python3.7/site-packages/requests/sessions.py", line 590, in post
    return self.request('POST', url, data=data, json=json, **kwargs)
  File "/workspace/.pip-modules/lib/python3.7/site-packages/pyquil/api/_base_connection.py", line 469, in request
    response = super().request(*args, **kwargs)
  File "/workspace/.pip-modules/lib/python3.7/site-packages/requests/sessions.py", line 542, in request
    resp = self.send(prep, **send_kwargs)
  File "/workspace/.pip-modules/lib/python3.7/site-packages/requests/sessions.py", line 655, in send
    r = adapter.send(request, **kwargs)
  File "/workspace/.pip-modules/lib/python3.7/site-packages/requests/adapters.py", line 516, in send
    raise ConnectionError(e, request=request)
requests.exceptions.ConnectionError: HTTPConnectionPool(host='127.0.0.1', port=5000): Max retries exceeded with url: / (Caused by NewConnectionError('<urllib3.connection.HTTPConnection object at 0x7f0271619750>: Failed to establish a new connection: [Errno 111] Connection refused'))

During handling of the above exception, another exception occurred:

Traceback (most recent call last):
  File "z-tutorial_vqe_parallel.py", line 123, in <module>
    dev1 = [qml.device("forest.qvm", device="4q-qvm") for _ in range(8)]
  File "z-tutorial_vqe_parallel.py", line 123, in <listcomp>
    dev1 = [qml.device("forest.qvm", device="4q-qvm") for _ in range(8)]
  File "/workspace/.pip-modules/lib/python3.7/site-packages/pennylane/__init__.py", line 198, in device
    return plugin_device_class(*args, **options)
  File "/workspace/.pip-modules/lib/python3.7/site-packages/pennylane_forest/qvm.py", line 120, in __init__
    self.qc = get_qc(device, as_qvm=True, noisy=noisy, connection=self.connection)
  File "/workspace/.pip-modules/lib/python3.7/site-packages/pyquil/api/_error_reporting.py", line 251, in wrapper
    val = func(*args, **kwargs)
  File "/workspace/.pip-modules/lib/python3.7/site-packages/pyquil/api/_quantum_computer.py", line 916, in get_qc
    compiler_timeout=compiler_timeout,
  File "/workspace/.pip-modules/lib/python3.7/site-packages/pyquil/api/_quantum_computer.py", line 779, in _get_unrestricted_qvm
    compiler_timeout=compiler_timeout,
  File "/workspace/.pip-modules/lib/python3.7/site-packages/pyquil/api/_quantum_computer.py", line 716, in _get_qvm_with_topology
    compiler_timeout=compiler_timeout,
  File "/workspace/.pip-modules/lib/python3.7/site-packages/pyquil/api/_quantum_computer.py", line 667, in _get_qvm_qc
    requires_executable=requires_executable,
  File "/workspace/.pip-modules/lib/python3.7/site-packages/pyquil/api/_quantum_computer.py", line 624, in _get_qvm_or_pyqvm
    connection=connection, noise_model=noise_model, requires_executable=requires_executable
  File "/workspace/.pip-modules/lib/python3.7/site-packages/pyquil/api/_error_reporting.py", line 251, in wrapper
    val = func(*args, **kwargs)
  File "/workspace/.pip-modules/lib/python3.7/site-packages/pyquil/api/_qvm.py", line 488, in __init__
    self.connect()
  File "/workspace/.pip-modules/lib/python3.7/site-packages/pyquil/api/_qvm.py", line 495, in connect
    raise QVMNotRunning(f"No QVM server running at {self.connection.sync_endpoint}")
pyquil.api._qvm.QVMNotRunning: No QVM server running at http://127.0.0.1:5000
